# Error Handling

This Python script is demonstrating the usage of try-except blocks to handle different types of errors during the runtime of a program. The script accepts two inputs, performs division, and handles potential errors that might occur.

```python
try: 
    a = int(input("Input a number: "))
    b = int(input("Input a number: "))
    result = a / b
    print("Result: ", result)
except ValueError:
    print("Please enter a numeric value")
except ZeroDivisionError:
    print("Cannot divide by zero")
except:
    print("An error occured somewhere in the program.")
```

Explanation:
- The `try` block contains code that might raise an exception during its execution.
- `a = int(input("Input a number: "))` and `b = int(input("Input a number: "))` are used to take two inputs from the user and convert them to integers.
- `result = a / b` calculates the division of `a` by `b`.
- The `print("Result: ", result)` statement displays the result of the division.

- If a `ValueError` occurs (which happens when the conversion to integer fails), it prints "Please enter a numeric value".
- If a `ZeroDivisionError` occurs (which happens when dividing by zero), it prints "Cannot divide by zero".
- If any other exception occurs, it prints "An error occurred somewhere in the program".

### Predictions:

1. **a = 1, b = 0**
   - The `ZeroDivisionError` will be triggered since b is zero, and the output will be "Cannot divide by zero".

2. **a = 0, b = 10**
   - The division is successful (0 divided by 10 is 0), and the output will be "Result: 0.0".

3. **a = “Hello”, b = 0**
   - A `ValueError` will occur since "Hello" cannot be converted to an integer. Hence, the output will be "Please enter a numeric value".

4. **a = 1, b = “Hello”**
   - A `ValueError` will occur when trying to convert "Hello" to an integer, and the output will be "Please enter a numeric value".

#### Another example
This Python script demonstrates the usage of nested try-except blocks for error handling while performing file operations. Here, the script attempts to open a file with a specific encoding, read its content, and handle any potential errors that might occur during these operations.

```python
try:
    file = open("improperly_encoded.txt", "r", encoding='utf-8')
    try:
        # Perform some file operations
        content = file.read()
        print(content)
        # Process the content
    except Exception as e:
        print("Error occurred while reading the file: {}".format(e))
    finally:
        file.close()  # Close the file
        print("File closed.")
except FileNotFoundError:
    print("File not found.")
except (OSError, PermissionError) as e:
    print(f"Error: {str(e)}")
```

Explanation:
- The outer `try` block contains code that attempts to open a file named "improperly_encoded.txt" with 'utf-8' encoding.
- Within this block, there is another `try` block that attempts to read the content of the file and print it to the console.
- If any exception occurs while reading the file, it will be caught by the inner `except` block, which prints a message along with the error description.
- The `finally` block executes after the inner try-except block, ensuring that the file is closed and a message "File closed." is printed to the console.
- If the file is not found, a `FileNotFoundError` is raised, which is caught by the corresponding `except` block, printing "File not found." to the console.
- If an `OSError` or `PermissionError` occurs, it will be caught by the last `except` block, which prints a message along with the error description.

Predicting the output of this script without executing depends on the actual circumstances of the file "improperly_encoded.txt". Here are some potential outcomes:

1. If the file "improperly_encoded.txt" does not exist in the directory where the script is being run, the output will be:
   ```
   File not found.
   ```

2. If the file exists but there is an issue with permissions (like not having read permissions), the output might be:
   ```
   Error: [specific error message describing the permission issue]
   ```

3. If the file exists, has proper permissions, but contains characters that cannot be decoded with 'utf-8' encoding, the output will be:
   ```
   Error occurred while reading the file: 'utf-8' codec can't decode byte [specific byte information] in position [specific position]: [specific error description]
   File closed.
   ```

4. If the file exists, has the proper permissions, and is properly encoded in 'utf-8', the output will be:
   ```
   [Content of the file]
   File closed.
   ```